2018-01-11 13:30:21,398 - bagit - ERROR - Bag directory S:\Staging\County_Records\Marriage_Bonds\MB_Cabarrrus does not exist
2018-01-11 13:37:35,835 - bagit - ERROR - Bag directory S:\Staging\County_Records\Marriage_Bonds\MB_Cabarrrus does not exist
2018-02-07 14:24:53,463 - bagit - ERROR - Bag directory S:\Staging\Special_Collections\Military_Collection\MilColl_CivilWar\MilColl_CivilWar_Maps\MilColl_CivilWar_Maps_003.TIF does not exist
2018-02-07 14:49:25,126 - bagit - ERROR - The following files do not have read permissions:
('S:\\Staging\\Special_Collections\\Military_Collection\\MilColl_WWI\\MilColl_WWI_6\\MilColl_WWI_6_Box3_Red_Cross_Histories\\MilColl_WWI_6_Box3_Folder20_Wake_County_Influenza_Epidemic_Volunteers\\MilColl_WWI_6_Box3_Folder20_Wake_County_Influenza_Epidemic_Volunteers_02.tif', 'S:\\Staging\\Special_Collections\\Military_Collection\\MilColl_WWI\\MilColl_WWI_6\\MilColl_WWI_6_Box3_Red_Cross_Histories\\MilColl_WWI_6_Box3_Folder20_Wake_County_Influenza_Epidemic_Volunteers\\MilColl_WWI_6_Box3_Folder20_Wake_County_Influenza_Epidemic_Volunteers_04.tif', 'S:\\Staging\\Special_Collections\\Military_Collection\\MilColl_WWI\\MilColl_WWI_6\\MilColl_WWI_6_Box3_Red_Cross_Histories\\MilColl_WWI_6_Box3_Folder20_Wake_County_Influenza_Epidemic_Volunteers\\MilColl_WWI_6_Box3_Folder20_Wake_County_Influenza_Epidemic_Volunteers_01.tif', 'S:\\Staging\\Special_Collections\\Military_Collection\\MilColl_WWI\\MilColl_WWI_6\\MilColl_WWI_6_Box3_Red_Cross_Histories\\MilColl_WWI_6_Box3_Folder20_Wake_County_Influenza_Epidemic_Volunteers\\MilColl_WWI_6_Box3_Folder20_Wake_County_Influenza_Epidemic_Volunteers_03.tif')
2018-02-07 14:49:25,126 - bagit - ERROR - An error occurred creating a bag in S:\Staging\Special_Collections\Military_Collection\MilColl_WWI\MilColl_WWI_6
Traceback (most recent call last):
  File "C:\virtualenvs\py36x64\Scripts\bagit.py", line 181, in make_bag
    raise BagError(_("Read permissions are required to calculate file fixities"))
bagit.BagError: Read permissions are required to calculate file fixities
2018-02-07 14:55:00,753 - bagit - ERROR - The following files do not have read permissions:
('S:\\Staging\\Special_Collections\\Military_Collection\\MilColl_WWI\\MilColl_WWI_6\\MilColl_WWI_6_Box3_Red_Cross_Histories\\MilColl_WWI_6_Box3_Folder20_Wake_County_Influenza_Epidemic_Volunteers\\MilColl_WWI_6_Box3_Folder20_Wake_County_Influenza_Epidemic_Volunteers_02.tif', 'S:\\Staging\\Special_Collections\\Military_Collection\\MilColl_WWI\\MilColl_WWI_6\\MilColl_WWI_6_Box3_Red_Cross_Histories\\MilColl_WWI_6_Box3_Folder20_Wake_County_Influenza_Epidemic_Volunteers\\MilColl_WWI_6_Box3_Folder20_Wake_County_Influenza_Epidemic_Volunteers_04.tif', 'S:\\Staging\\Special_Collections\\Military_Collection\\MilColl_WWI\\MilColl_WWI_6\\MilColl_WWI_6_Box3_Red_Cross_Histories\\MilColl_WWI_6_Box3_Folder20_Wake_County_Influenza_Epidemic_Volunteers\\MilColl_WWI_6_Box3_Folder20_Wake_County_Influenza_Epidemic_Volunteers_01.tif', 'S:\\Staging\\Special_Collections\\Military_Collection\\MilColl_WWI\\MilColl_WWI_6\\MilColl_WWI_6_Box3_Red_Cross_Histories\\MilColl_WWI_6_Box3_Folder20_Wake_County_Influenza_Epidemic_Volunteers\\MilColl_WWI_6_Box3_Folder20_Wake_County_Influenza_Epidemic_Volunteers_03.tif')
2018-02-07 14:55:00,753 - bagit - ERROR - An error occurred creating a bag in S:\Staging\Special_Collections\Military_Collection\MilColl_WWI\MilColl_WWI_6
Traceback (most recent call last):
  File "C:\virtualenvs\py36x64\Scripts\bagit.py", line 181, in make_bag
    raise BagError(_("Read permissions are required to calculate file fixities"))
bagit.BagError: Read permissions are required to calculate file fixities
2018-02-07 16:16:13,902 - bagit - ERROR - Bag directory S:\Staging\Special_Collections\Organization_Records\ORG_195_Women_In_Action_Durham_Chapter does not exist
2018-02-08 07:49:57,318 - bagit - ERROR - An error occurred creating a bag in S:\Staging\Special_Collections\Organization_Records\ORG_113_NC_League_Women_Voters_Wake_County
multiprocessing.pool.RemoteTraceback: 
"""
Traceback (most recent call last):
  File "c:\users\jgibson5\appdata\local\programs\python\python36\Lib\multiprocessing\pool.py", line 119, in worker
    result = (True, func(*args, **kwds))
  File "c:\users\jgibson5\appdata\local\programs\python\python36\Lib\multiprocessing\pool.py", line 44, in mapstar
    return list(map(*args))
  File "C:\virtualenvs\py36x64\Scripts\bagit.py", line 1264, in generate_manifest_lines
    with open(filename, 'rb') as f:
FileNotFoundError: [Errno 2] No such file or directory: 'data/ORG_113_NC_League_Women_Voters_Wake_County_Synopsis_Local_Programs_1953_1968/ORG_113_NC_League_Women_Voters_Wake_County_Synopsis_Local_Programs_1953_1968_001.tif'
"""

The above exception was the direct cause of the following exception:

Traceback (most recent call last):
  File "C:\virtualenvs\py36x64\Scripts\bagit.py", line 207, in make_bag
    encoding=encoding)
  File "C:\virtualenvs\py36x64\Scripts\bagit.py", line 1117, in make_manifests
    checksums = pool.map(manifest_line_generator, _walk(data_dir))
  File "c:\users\jgibson5\appdata\local\programs\python\python36\Lib\multiprocessing\pool.py", line 266, in map
    return self._map_async(func, iterable, mapstar, chunksize).get()
  File "c:\users\jgibson5\appdata\local\programs\python\python36\Lib\multiprocessing\pool.py", line 644, in get
    raise self._value
FileNotFoundError: [Errno 2] No such file or directory: 'data/ORG_113_NC_League_Women_Voters_Wake_County_Synopsis_Local_Programs_1953_1968/ORG_113_NC_League_Women_Voters_Wake_County_Synopsis_Local_Programs_1953_1968_001.tif'
